<?xml version="1.0" ?>
<!-- =================================================================================== -->
<!-- |    This document was autogenerated by xacro from iiwa_striker.urdf.xacro        | -->
<!-- |    EDITING THIS FILE BY HAND IS NOT RECOMMENDED                                 | -->
<!-- =================================================================================== -->
<robot name="iiwa_1">
  <material name="Black">
    <color rgba="0.0 0.0 0.0 1.0"/>
  </material>
  <material name="Blue">
    <color rgba="0.0 0.0 0.8 1.0"/>
  </material>
  <material name="Green">
    <color rgba="0.0 0.8 0.0 1.0"/>
  </material>
  <material name="Grey">
    <color rgba="0.4 0.4 0.4 1.0"/>
  </material>
  <material name="Orange">
    <color rgba="1.0 0.4235294117647059 0.0392156862745098 1.0"/>
  </material>
  <material name="Brown">
    <color rgba="0.8705882352941177 0.8117647058823529 0.7647058823529411 1.0"/>
  </material>
  <material name="Red">
    <color rgba="0.8 0.0 0.0 1.0"/>
  </material>
  <material name="White">
    <color rgba="1.0 1.0 1.0 1.0"/>
  </material>
  <material name="LightGrey">
    <color rgba="0.3 0.3 0.3 1.0"/>
  </material>
  <link name="world"/>
  <!--joint between {parent} and link_0-->
  <joint name="iiwa_1/base_joint" type="fixed">
    <origin rpy="0 0 0" xyz="0 0 0"/>
    <parent link="world"/>
    <child link="iiwa_1/link_0"/>
  </joint>
  <link name="iiwa_1/link_0">
    <inertial>
      <origin rpy="0 0 0" xyz="-0.1 0 0.07"/>
      <mass value="5"/>
      <inertia ixx="0.05" ixy="0" ixz="0" iyy="0.06" iyz="0" izz="0.03"/>
    </inertial>
    <visual>
      <origin rpy="0 0 0" xyz="0 0 0"/>
      <geometry>
        <mesh filename="meshes/visual/link_0.stl"/>
      </geometry>
      <material name="Grey"/>
    </visual>
    <collision>
      <origin rpy="0 0 0" xyz="0 0 0"/>
      <geometry>
        <mesh filename="meshes/collision/link_0.stl"/>
      </geometry>
      <material name="Grey"/>
    </collision>
    <self_collision_checking>
      <origin rpy="0 0 0" xyz="0 0 0"/>
      <geometry>
        <capsule length="0.25" radius="0.15"/>
      </geometry>
    </self_collision_checking>
  </link>
  <!-- joint between link_0 and link_1 -->
  <joint name="iiwa_1/joint_1" type="revolute">
    <parent link="iiwa_1/link_0"/>
    <child link="iiwa_1/link_1"/>
    <origin rpy="0 0 0" xyz="0 0 0.1575"/>
    <axis xyz="0 0 1"/>
    <limit effort="320" lower="-2.9670597283903604" upper="2.9670597283903604" velocity="1.4835298641951802"/>
    <safety_controller k_position="100" k_velocity="10" soft_lower_limit="-2.9321531433504737" soft_upper_limit="2.9321531433504737"/>
    <!--      <dynamics damping="0.24150"  friction="0.31909"/> &lt;!&ndash; ETH &ndash;&gt;-->
    <dynamics damping="0.330320" friction="0.384477"/>
  </joint>
  <link name="iiwa_1/link_1">
    <inertial>
      <!-- ETH
          <origin xyz="-0.003508 0.001602 -0.03139" rpy="0 0 0"/>
          <mass value="3.947808"/>
          <inertia ixx="0.004554"  ixy="0.00000"  ixz="-0.00000" iyy="0.00454" iyz="0.00001" izz="0.00029" />
          -->
      <mass value="2.356723"/>
      <origin rpy="0 0 0" xyz="0.000000 0.000000 -0.249990"/>
      <!--          <inertia ixx="0.099939"  ixy="-0.000029"  iyy="0.099716" ixz="-0.000026" iyz="0.000099" izz="0.001000" />-->
      <inertia ixx="0.1" ixy="0" ixz="0" iyy="0.1" iyz="0" izz="0.01"/>
    </inertial>
    <visual>
      <origin rpy="0 0 0" xyz="0 0 0"/>
      <geometry>
        <mesh filename="meshes/visual/link_1.stl"/>
      </geometry>
      <material name="Orange"/>
    </visual>
    <collision>
      <origin rpy="0 0 0" xyz="0 0 0"/>
      <geometry>
        <mesh filename="meshes/collision/link_1.stl"/>
      </geometry>
      <material name="Orange"/>
    </collision>
  </link>
  <!-- joint between link_1 and link_2 -->
  <joint name="iiwa_1/joint_2" type="revolute">
    <parent link="iiwa_1/link_1"/>
    <child link="iiwa_1/link_2"/>
    <origin rpy="1.5707963267948966   0 3.141592653589793" xyz="0 0 0.2025"/>
    <axis xyz="0 0 1"/>
    <limit effort="320" lower="-2.0943951023931953" upper="2.0943951023931953" velocity="1.4835298641951802"/>
    <safety_controller k_position="100" k_velocity="10" soft_lower_limit="-2.0594885173533086" soft_upper_limit="2.0594885173533086"/>
    <!--      <dynamics damping="0.37328"  friction="0.18130"/> &lt;!&ndash; ETH &ndash;&gt;-->
    <dynamics damping="0.212160" friction="0.496333"/>
  </joint>
  <link name="iiwa_1/link_2">
    <inertial>
      <!-- ETH
          <mass value="4.502752"/>
          <origin xyz="-0.007671 0.166693  -0.003551" rpy="0 0 0"/>
          <inertia ixx="0.00032"  ixy="0.00000"  ixz="0.000007" iyy="0.000100" iyz="-0.000003" izz="0.000419" />
          -->
      <mass value="6.000000"/>
      <origin rpy="0 0 0" xyz="-0.004595 0.150863 0.028496"/>
      <inertia ixx="0.030001" ixy="-0.000999" ixz="0.000999" iyy="0.010000" iyz="-0.000999" izz="0.030001"/>
    </inertial>
    <visual>
      <origin rpy="0 0 0" xyz="0 0 0"/>
      <geometry>
        <mesh filename="meshes/visual/link_2.stl"/>
      </geometry>
      <material name="Orange"/>
    </visual>
    <collision>
      <origin rpy="0 0 0" xyz="0 0 0"/>
      <geometry>
        <mesh filename="meshes/collision/link_2.stl"/>
      </geometry>
      <material name="Orange"/>
    </collision>
  </link>
  <!-- joint between link_2 and link_3 -->
  <joint name="iiwa_1/joint_3" type="revolute">
    <parent link="iiwa_1/link_2"/>
    <child link="iiwa_1/link_3"/>
    <origin rpy="1.5707963267948966 0 3.141592653589793" xyz="0 0.2045 0"/>
    <axis xyz="0 0 1"/>
    <limit effort="176" lower="-2.9670597283903604" upper="2.9670597283903604" velocity="1.7453292519943295"/>
    <safety_controller k_position="100" k_velocity="10" soft_lower_limit="-2.9321531433504737" soft_upper_limit="2.9321531433504737"/>
    <!--      <dynamics damping="0.11025"  friction="0.07302"/> &lt;!&ndash; ETH &ndash;&gt;-->
    <dynamics damping="0.100000" friction="0.173951"/>
  </joint>
  <link name="iiwa_1/link_3">
    <inertial>
      <!-- ETH
          <mass value="2.455197"/>
          <origin xyz="-0.002246 -0.034918 -0.02652" rpy="0 0 0"/>
          <inertia ixx="0.002233"  ixy="-0.000046"  ixz="0.000068" iyy="0.002191" iyz="0.000072" izz="0.000725" />
          -->
      <mass value="6.00000"/>
      <origin rpy="0 0 0" xyz="-0.006630 -0.001947 -0.057071"/>
      <inertia ixx="0.03001" ixy="-0.000999" ixz="0.000999" iyy="0.030001" iyz="-0.000999" izz="0.010000"/>
    </inertial>
    <visual>
      <origin rpy="0 0 0" xyz="0 0 0"/>
      <geometry>
        <mesh filename="meshes/visual/link_3.stl"/>
      </geometry>
      <material name="Orange"/>
    </visual>
    <collision>
      <origin rpy="0 0 0" xyz="0 0 0"/>
      <geometry>
        <mesh filename="meshes/collision/link_3.stl"/>
      </geometry>
      <material name="Orange"/>
    </collision>
  </link>
  <!-- joint between link_3 and link_4 -->
  <joint name="iiwa_1/joint_4" type="revolute">
    <parent link="iiwa_1/link_3"/>
    <child link="iiwa_1/link_4"/>
    <origin rpy="1.5707963267948966 0 0" xyz="0 0 0.2155"/>
    <axis xyz="0 0 1"/>
    <limit effort="176" lower="-2.0943951023931953" upper="2.0943951023931953" velocity="1.3089969389957472"/>
    <safety_controller k_position="100" k_velocity="10" soft_lower_limit="-2.0594885173533086" soft_upper_limit="2.0594885173533086"/>
    <!--      <dynamics damping="0.10000"  friction="0.17671"/> &lt;!&ndash; ETH &ndash;&gt;-->
    <dynamics damping="0.219041" friction="0.375100"/>
  </joint>
  <link name="iiwa_1/link_4">
    <inertial>
      <!-- ETH
          <mass value="2.611550"/>
          <origin xyz="0.000196 -0.052679 0.038182" rpy="0 0 0"/>
          <inertia ixx="0.038444"  ixy="0.000880"  ixz="-0.001120" iyy="0.011437" iyz="-0.001113" izz=" 0.049880" />
          -->
      <mass value="1.224529"/>
      <origin rpy="0 0 0" xyz="0.044234 0.050000 0.006944"/>
      <inertia ixx="0.003001" ixy="0.000099" ixz="-0.000099" iyy="0.001000" iyz="0.000099" izz="0.003001"/>
    </inertial>
    <visual>
      <origin rpy="0 0 0" xyz="0 0 0"/>
      <geometry>
        <mesh filename="meshes/visual/link_4.stl"/>
      </geometry>
      <material name="Orange"/>
    </visual>
    <collision>
      <origin rpy="0 0 0" xyz="0 0 0"/>
      <geometry>
        <mesh filename="meshes/collision/link_4.stl"/>
      </geometry>
      <material name="Orange"/>
    </collision>
  </link>
  <!-- joint between link_4 and link_5 -->
  <joint name="iiwa_1/joint_5" type="revolute">
    <parent link="iiwa_1/link_4"/>
    <child link="iiwa_1/link_5"/>
    <origin rpy="-1.5707963267948966 3.141592653589793 0" xyz="0 0.1845 0"/>
    <axis xyz="0 0 1"/>
    <limit effort="110" lower="-2.9670597283903604" upper="2.9670597283903604" velocity="2.2689280275926285"/>
    <safety_controller k_position="100" k_velocity="10" soft_lower_limit="-2.9321531433504737" soft_upper_limit="2.9321531433504737"/>
    <!--      <dynamics damping="0.10000"  friction="0.03463"/> &lt;!&ndash; ETH &ndash;&gt;-->
    <dynamics damping="0.185923" friction="0.481099"/>
  </joint>
  <link name="iiwa_1/link_5">
    <inertial>
      <!-- ETH
          <mass value="3.410009"/>
          <origin xyz="0.000054  -0.002367 -0.21134" rpy="0 0 0"/>
          <inertia ixx="0.002769"  ixy="-0.000008"  ixz="0.000006" iyy="0.002842" iyz="-0.000001" izz="0.000117" />
          -->
      <mass value="6.00000"/>
      <origin rpy="0 0 0" xyz="-0.002930 0.015256 0.035846"/>
      <inertia ixx="0.003001" ixy="-0.000099" ixz="-0.000099" iyy="0.003001" iyz="0.000099" izz="0.001000"/>
    </inertial>
    <visual>
      <origin rpy="0 0 0" xyz="0 0 0"/>
      <geometry>
        <mesh filename="meshes/visual/link_5.stl"/>
      </geometry>
      <material name="Orange"/>
    </visual>
    <collision>
      <origin rpy="0 0 0" xyz="0 0 0"/>
      <geometry>
        <mesh filename="meshes/collision/link_5.stl"/>
      </geometry>
      <material name="Orange"/>
    </collision>
  </link>
  <!-- joint between link_5 and link_6 -->
  <joint name="iiwa_1/joint_6" type="revolute">
    <parent link="iiwa_1/link_5"/>
    <child link="iiwa_1/link_6"/>
    <origin rpy="1.5707963267948966 0 0" xyz="0 0 0.2155"/>
    <axis xyz="0 0 1"/>
    <limit effort="40" lower="-2.0943951023931953" upper="2.0943951023931953" velocity="2.356194490192345"/>
    <safety_controller k_position="100" k_velocity="10" soft_lower_limit="-2.0594885173533086" soft_upper_limit="2.0594885173533086"/>
    <!--      <dynamics damping="0.12484"  friction="0.13391"/> &lt;!&ndash; ETH &ndash;&gt;-->
    <dynamics damping="0.100000" friction="0.196149"/>
  </joint>
  <link name="iiwa_1/link_6">
    <inertial>
      <!-- ETH
          <mass value="3.387949"/>
          <origin xyz="0.000492  0.020190  -0.027496" rpy="0 0 0"/>
          <inertia ixx="0.000500"  ixy="-0.000050"  ixz="-0.000024" iyy="0.002809" iyz="-0.000041" izz="0.002315" />
          -->
      <mass value="1.410742"/>
      <origin rpy="0 0 0" xyz="0.015383 -0.046263 0.011131"/>
      <inertia ixx="0.001000" ixy="0.000099" ixz="0.000099" iyy="0.001000" iyz="0.000099" izz="0.001000"/>
    </inertial>
    <visual>
      <origin rpy="0 0 0" xyz="0 0 0"/>
      <geometry>
        <mesh filename="meshes/visual/link_6.stl"/>
      </geometry>
      <material name="Orange"/>
    </visual>
    <collision>
      <origin rpy="0 0 0" xyz="0 0 0"/>
      <geometry>
        <mesh filename="meshes/collision/link_6.stl"/>
      </geometry>
      <material name="Orange"/>
    </collision>
  </link>
  <!-- joint between link_6 and link_7 -->
  <joint name="iiwa_1/joint_7" type="revolute">
    <parent link="iiwa_1/link_6"/>
    <child link="iiwa_1/link_7"/>
    <origin rpy="-1.5707963267948966 3.141592653589793 0" xyz="0 0.081 0"/>
    <axis xyz="0 0 1"/>
    <limit effort="40" lower="-3.0543261909900763" upper="3.0543261909900763" velocity="2.356194490192345"/>
    <safety_controller k_position="100" k_velocity="10" soft_lower_limit="-3.01941960595019" soft_upper_limit="3.01941960595019"/>
    <!--      <dynamics damping="0.10000"  friction="0.08710"/> &lt;!&ndash; ETH &ndash;&gt;-->
    <dynamics damping="0.100000" friction="0.299238"/>
  </joint>
  <link name="iiwa_1/link_7">
    <inertial>
      <!-- ETH
          <mass value="0.354321"/>
          <origin xyz="-0.034656 -0.023242 0.07138" rpy="0 0 0"/>
          <inertia ixx="0.007946"  ixy="0.000221"  ixz="-0.000294" iyy=" 0.010889" iyz="-0.000294" izz="0.002944" />
          -->
      <mass value="1.00000"/>
      <origin rpy="0 0 0" xyz="0.001241 0.004168 0.100000"/>
      <inertia ixx="0.001000" ixy="-0.000099" ixz="-0.000099" iyy="0.001000" iyz="0.000099" izz="0.001000"/>
    </inertial>
    <visual>
      <origin rpy="0 0 0" xyz="0 0 0"/>
      <geometry>
        <mesh filename="meshes/visual/link_7.stl"/>
      </geometry>
      <material name="Grey"/>
    </visual>
    <collision>
      <origin rpy="0 0 0" xyz="0 0 0"/>
      <geometry>
        <mesh filename="meshes/collision/link_7.stl"/>
      </geometry>
      <material name="Grey"/>
    </collision>
  </link>
  <joint name="iiwa_1/joint_ee" type="fixed">
    <parent link="iiwa_1/link_7"/>
    <child link="iiwa_1/link_ee"/>
    <origin rpy="0 0 0" xyz="0 0 0.07"/>
  </joint>
  <link name="iiwa_1/link_ee">
    <inertial>
      <origin rpy="0 0 0" xyz="0 0 0.0"/>
      <mass value="0.0"/>
      <inertia ixx="0.0" ixy="0.0" ixz="0.0" iyy="0.0" iyz="0.0" izz="0.0"/>
    </inertial>
  </link>
  <joint name="iiwa_1/striker" type="fixed">
    <parent link="iiwa_1/link_ee"/>
    <child link="iiwa_1/striker_base"/>
    <origin rpy="0 0 0" xyz="0.0 0.0 0.0"/>
  </joint>
  <link name="iiwa_1/striker_base">
    <inertial>
      <origin rpy="0 0 0" xyz="0 0 0.156"/>
      <mass value="0.350"/>
      <!--                <inertia ixx="0.000297" ixy="0.0" ixz="0.0"-->
      <!--                         iyy="0.000271" iyz="0.0" izz="0.0000653"/>-->
      <inertia ixx="0.005" ixy="0.0" ixz="0.0" iyy="0.005" iyz="0.0" izz="0.001"/>
    </inertial>
    <visual>
      <origin rpy="0 0.0 0" xyz="0 0 0"/>
      <geometry>
        <mesh filename="meshes/striker/visual/EE_arm.stl"/>
      </geometry>
      <material name="LightGrey"/>
    </visual>
    <collision>
      <origin rpy="0 0 0" xyz="0 0 0"/>
      <geometry>
        <mesh filename="meshes/striker/collision/EE_arm_collision.stl"/>
      </geometry>
    </collision>
  </link>
  <joint name="iiwa_1/extension" type="fixed">
    <parent link="iiwa_1/link_7"/>
    <child link="iiwa_1/extension_tip"/>
    <origin rpy="0 0 0" xyz="0.0 0.0 0.515"/>
  </joint>
  <link name="iiwa_1/extension_tip">
    <inertial>
      <origin rpy="0 0 0" xyz="0 0 0.0"/>
      <mass value="0.01"/>
      <inertia ixx="0.0001" ixy="0.0" ixz="0.0" iyy="0.0001" iyz="0.0" izz="0.0001"/>
    </inertial>
  </link>
  <joint name="iiwa_1/striker_joint_1" type="revolute">
    <parent link="iiwa_1/striker_base"/>
    <child link="iiwa_1/striker_joint_link"/>
    <origin rpy="0 0 0" xyz="0.0 0.0 0.515"/>
    <axis xyz="0 1 0"/>
    <limit effort="10" lower="-1.5707963267948966" upper="1.5707963267948966" velocity="3.1415926"/>
    <safety_controller k_position="100" k_velocity="2" soft_lower_limit="-2.094395102" soft_upper_limit="2.094395102"/>
    <dynamics damping="0.01"/>
  </joint>
  <link name="iiwa_1/striker_joint_link">
    <inertial>
      <origin rpy="0 0 0" xyz="0 0.0 0"/>
      <mass value="0.1"/>
      <inertia ixx="0.001" ixy="0.0" ixz="0.0" iyy="0.001" iyz="0.0" izz="0.001"/>
    </inertial>
  </link>
  <joint name="iiwa_1/striker_joint_2" type="revolute">
    <parent link="iiwa_1/striker_joint_link"/>
    <child link="iiwa_1/striker_mallet"/>
    <origin rpy="0 0 0" xyz="0.0 0.0 0.0"/>
    <axis xyz="1 0 0"/>
    <limit effort="10" lower="-1.5707963267948966" upper="1.5707963267948966" velocity="3.1415926"/>
    <safety_controller k_position="100" k_velocity="2" soft_lower_limit="-2.094395102" soft_upper_limit="2.094395102"/>
    <dynamics damping="0.01"/>
  </joint>
  <link name="iiwa_1/striker_mallet">
    <inertial>
      <origin rpy="0 0 0" xyz="0 0.0 0.078"/>
      <mass value="0.183"/>
      <inertia ixx="0.0001" ixy="0.0" ixz="0.0" iyy="0.0001" iyz="0.0" izz="0.0001"/>
    </inertial>
    <visual>
      <origin rpy="0.0 0.0 0" xyz="0 0.0 0.0"/>
      <geometry>
        <!--                    <mesh filename="meshes/striker/visual/EE_mallet.stl"/>-->
        <mesh filename="meshes/striker/visual/EE_mallet_short.stl"/>
      </geometry>
      <material name="LightGrey"/>
    </visual>
    <collision>
      <origin rpy="0.0 0.0 0" xyz="0 0.0 0.0"/>
      <geometry>
        <!--                    <mesh filename="meshes/striker/collision/EE_mallet_collision.stl"/>-->
        <mesh filename="meshes/striker/collision/EE_mallet_short_collision.stl"/>
      </geometry>
    </collision>
  </link>
  <joint name="iiwa_1/striker_mallet_fix" type="fixed">
    <parent link="iiwa_1/striker_mallet"/>
    <child link="iiwa_1/striker_mallet_tip"/>
    <!--            <origin xyz="0.0 0.0 0.095" rpy="0 0 0"/>-->
    <origin rpy="0 0 0" xyz="0.0 0.0 0.0505"/>
    <axis xyz="1 0 0"/>
  </joint>
  <!--  The striker frame is here defined -->
  <link name="iiwa_1/striker_mallet_tip">
    <inertial>
      <origin rpy="0 0 0" xyz="0 0 0.0"/>
      <mass value="0.1"/>
      <inertia ixx="0.0001" ixy="0.0" ixz="0.0" iyy="0.0001" iyz="0.0" izz="0.0001"/>
    </inertial>
  </link>
</robot>

